Workbook

Sheet README
A1: Helios Instruments Pvt. Ltd. — Business Travel Expense Register, 2025
A3: PURPOSE | B3: Fictional but internally consistent travel & expense dataset for demos, audit-workflow testing, dashboards and pivot-table practice.
A4: Coverage | B4: 1 January 2025 to 31 December 2025 — 138 business trips, 2,954 individual expense line items.
A5: Grain | B5: One row per individual expense claim (a single receipt).
A6: Employees | B6: 24 travellers across Sales, Field Engineering, Product, Marketing, Customer Success, Finance, Operations and Executive.
A7: Currency | B7: Claims are recorded in the local currency of the destination and converted to US dollars at a fixed period-average FX rate.
A9: TABS
A10: Expense Details | B10: The full register — 37 columns covering who, where, when, what, how much, tax, policy check and the approval trail.
A11: Trip Summary | B11: One row per trip: duration, line-item count, total spend, cost per day, policy breaches and billability.
A12: Employee Summary | B12: Spend per traveller, split by airfare / lodging / meals / ground transport, with policy breaches and missing receipts.
A13: Category by Month | B13: Category x month matrix with share of spend and the policy limit for each category.
A14: Policy Exceptions | B14: Audit view — every claim over its limit or missing a receipt.
A16: COLOUR LEGEND
A17: Blue text | B17: Hardcoded input value — amounts, FX rates, dates, statuses.
A18: Black text | B18: Calculated by formula — do not overwrite.
A19: Green text | B19: Live link to a cell on another tab.
A20: Yellow fill | B20: Key assumption you may want to change.
A21: Red fill | B21: Flagged for review on the Policy Exceptions tab.
A23: HOW FIGURES ARE DERIVED
A24: Amount (USD) | B24: Amount (Local) x FX Rate to USD
A25: VAT / Tax (USD) | B25: Amount (USD) - (Amount (USD) / (1 + VAT Rate)) — tax is inclusive
A26: Net of Tax (USD) | B26: Amount (USD) - VAT / Tax (USD)
A27: Over Policy? | B27: Yes when Amount (USD) exceeds the category Policy Limit
A28: Variance vs Limit | B28: Amount (USD) - Policy Limit (USD); negative means under budget
A29: Reimbursable (USD) | B29: Zero for corporate-card and rejected claims; otherwise the full amount, since only out-of-pocket spend is paid back
A30: Days to Reimburse | B30: Date Reimbursed - Date Submitted
A32: EXPENSE POLICY LIMITS APPLIED
B33: Per-claim caps. Lodging and car rental limits are multiplied by the number of nights or days on the trip.
A35: Category | B35: Policy Limit (USD)
A36: Airfare | B36: 1400
A37: Hotel / Lodging | B37: 280
A38: Meals - Breakfast | B38: 25
A39: Meals - Lunch | B39: 35
A40: Meals - Dinner | B40: 75
A41: Client Entertainment | B41: 200
A42: Ground Transport - Taxi | B42: 60
A43: Ground Transport - Rail | B43: 150
A44: Car Rental | B44: 120
A45: Fuel / Mileage | B45: 90
A46: Parking & Tolls | B46: 45
...

Sheet Expense Details
A1: Expense ID | B1: Employee ID | C1: Employee Name | D1: Department | E1: Job Title | F1: Manager / Approver | G1: Trip ID | H1: Trip Purpose | I1: Destination City | J1: Destination Country | K1: Trip Start | L1: Trip End | M1: Expense Date | N1: Month | O1: Expense Category | P1: Description | Q1: Merchant / Vendor | R1: Payment Method | S1: Currency | T1: Amount (Local) | U1: FX Rate to USD | V1: Amount (USD) | W1: VAT / Tax Rate | X1: VAT / Tax (USD) | Y1: Net of Tax (USD) | Z1: Policy Limit (USD) | AA1: Over Policy? | AB1: Variance vs Limit (USD) | AC1: Receipt Attached | AD1: Billable to Client | AE1: Client / Project Code | AF1: Reimbursable (USD) | AG1: Approval Status | AH1: Date Submitted | AI1: Date Approved | AJ1: Date Reimbursed | AK1: Days to Reimburse
A2: EXP-00001 | B2: EMP-1103 | C2: Rohit Malhotra | D2: Sales | E2: Account Executive | F2: Ananya Sengupta | G2: TRP-2025-061 | H2: Client Meeting | I2: London | J2: United Kingdom | K2: 45658 | L2: 45661 | M2: 45658 | N2: 2025-01 | O2: Airfare | P2: Round trip HQ - London, economy | Q2: Lufthansa | R2: Corporate Card | S2: GBP | T2: 1219.76 | U2: 1.272 | V2: =T2*U2 -> 1551.5347 | W2: 0 | X2: =V2-(V2/(1+W2)) -> 0 | Y2: =V2-X2 -> 1551.5347 | Z2: 1400 | AA2: =IF(V2>Z2,"Yes","No") -> Yes | AB2: =V2-Z2 -> 151.53472 | AC2: Yes | AD2: No | AE2: INTERNAL-0000 | AF2: =IF(AG2="Rejected",0,IF(R2="Corporate Card",0,V2)) -> 0 | AG2: Approved | AH2: 45667 | AI2: 45672 | AJ2: 45686 | AK2: =IF(AJ2="","",AJ2-AH2) -> 19
A3: EXP-00002 | B3: EMP-1103 | C3: Rohit Malhotra | D3: Sales | E3: Account Executive | F3: Ananya Sengupta | G3: TRP-2025-061 | H3: Client Meeting | I3: London | J3: United Kingdom | K3: 45658 | L3: 45661 | M3: 45658 | N3: 2025-01 | O3: Baggage & Excess Fees | P3: Checked demo equipment | Q3: Emirates | R3: Personal Card (Reimbursable) | S3: GBP | T3: 64.39 | U3: 1.272 | V3: =T3*U3 -> 81.90408 | W3: 0 | X3: =V3-(V3/(1+W3)) -> 0 | Y3: =V3-X3 -> 81.90408 | Z3: 120 | AA3: =IF(V3>Z3,"Yes","No") -> No | AB3: =V3-Z3 -> -38.09592 | AC3: Yes | AD3: No | AE3: INTERNAL-0000 | AF3: =IF(AG3="Rejected",0,IF(R3="Corporate Card",0,V3)) -> 81.90408 | AG3: Approved | AH3: 45667 | AI3: 45672 | AJ3: 45686 | AK3: =IF(AJ3="","",AJ3-AH3) -> 19
A4: EXP-00003 | B4: EMP-1103 | C4: Rohit Malhotra | D4: Sales | E4: Account Executive | F4: Ananya Sengupta | G4: TRP-2025-061 | H4: Client Meeting | I4: London | J4: United Kingdom | K4: 45658 | L4: 45661 | M4: 45658 | N4: 2025-01 | O4: Meals - Breakfast | P4: Individual meal | Q4: Cafe Nero | R4: Corporate Card | S4: GBP | T4: 24.22 | U4: 1.272 | V4: =T4*U4 -> 30.80784 | W4: 0.2 | X4: =V4-(V4/(1+W4)) -> 5.13464 | Y4: =V4-X4 -> 25.6732 | Z4: 25 | AA4: =IF(V4>Z4,"Yes","No") -> Yes | AB4: =V4-Z4 -> 5.80784 | AC4: Yes | AD4: No | AE4: INTERNAL-0000 | AF4: =IF(AG4="Rejected",0,IF(R4="Corporate Card",0,V4)) -> 0 | AG4: Approved | AH4: 45667 | AI4: 45672 | AJ4: 45686 | AK4: =IF(AJ4="","",AJ4-AH4) -> 19
A5: EXP-00004 | B5: EMP-1103 | C5: Rohit Malhotra | D5: Sales | E5: Account Executive | F5: Ananya Sengupta | G5: TRP-2025-061 | H5: Client Meeting | I5: London | J5: United Kingdom | K5: 45658 | L5: 45661 | M5: 45659 | N5: 2025-01 | O5: Ground Transport - Taxi | P5: Airport / client site transfer | Q5: Local Taxi | R5: Personal Card (Reimbursable) | S5: GBP | T5: 28 | U5: 1.272 | V5: =T5*U5 -> 35.616 | W5: 0.2 | X5: =V5-(V5/(1+W5)) -> 5.936 | Y5: =V5-X5 -> 29.68 | Z5: 60 | AA5: =IF(V5>Z5,"Yes","No") -> No | AB5: =V5-Z5 -> -24.384 | AC5: Yes | AD5: No | AE5: INTERNAL-0000 | AF5: =IF(AG5="Rejected",0,IF(R5="Corporate Card",0,V5)) -> 35.616 | AG5: Approved | AH5: 45667 | AI5: 45672 | AJ5: 45686 | AK5: =IF(AJ5="","",AJ5-AH5) -> 19
A6: EXP-00005 | B6: EMP-1103 | C6: Rohit Malhotra | D6: Sales | E6: Account Executive | F6: Ananya Sengupta | G6: TRP-2025-061 | H6: Client Meeting | I6: London | J6: United Kingdom | K6: 45658 | L6: 45661 | M6: 45659 | N6: 2025-01 | O6: Hotel / Lodging | P6: 3 night(s) @ standard rate | Q6: Marriott | R6: Corporate Card | S6: GBP | T6: 574.25 | U6: 1.272 | V6: =T6*U6 -> 730.446 | W6: 0.2 | X6: =V6-(V6/(1+W6)) -> 121.741 | Y6: =V6-X6 -> 608.705 | Z6: 840 | AA6: =IF(V6>Z6,"Yes","No") -> No | AB6: =V6-Z6 -> -109.554 | AC6: Yes | AD6: No | AE6: INTERNAL-0000 | AF6: =IF(AG6="Rejected",0,IF(R6="Corporate Card",0,V6)) -> 0 | AG6: Approved | AH6: 45667 | AI6: 45672 | AJ6: 45686 | AK6: =IF(AJ6="","",AJ6-AH6) -> 19
A7: EXP-00006 | B7: EMP-1103 | C7: Rohit Malhotra | D7: Sales | E7: Account Executive | F7: Ananya Sengupta | G7: TRP-2025-061 | H7: Client Meeting | I7: London | J7: United Kingdom | K7: 45658 | L7: 45661 | M7: 45659 | N7: 2025-01 | O7: Meals - Breakfast | P7: Individual meal | Q7: Hotel Restaurant | R7: Cash (Reimbursable) | S7: GBP | T7: 11.21 | U7: 1.272 | V7: =T7*U7 -> 14.25912 | W7: 0.2 | X7: =V7-(V7/(1+W7)) -> 2.37652 | Y7: =V7-X7 -> 11.8826 | Z7: 25 | AA7: =IF(V7>Z7,"Yes","No") -> No | AB7: =V7-Z7 -> -10.74088 | AC7: Yes | AD7: No | AE7: INTERNAL-0000 | AF7: =IF(AG7="Rejected",0,IF(R7="Corporate Card",0,V7)) -> 14.25912 | AG7: Approved | AH7: 45667 | AI7: 45672 | AJ7: 45686 | AK7: =IF(AJ7="","",AJ7-AH7) -> 19
A8: EXP-00007 | B8: EMP-1103 | C8: Rohit Malhotra | D8: Sales | E8: Account Executive | F8: Ananya Sengupta | G8: TRP-2025-061 | H8: Client Meeting | I8: London | J8: United Kingdom | K8: 45658 | L8: 45661 | M8: 45659 | N8: 2025-01 | O8: Meals - Dinner | P8: Party of 4 | Q8: Brasserie Lyon | R8: Corporate Card | S8: GBP | T8: 41.88 | U8: 1.272 | V8: =T8*U8 -> 53.27136 | W8: 0.2 | X8: =V8-(V8/(1+W8)) -> 8.87856 | Y8: =V8-X8 -> 44.3928 | Z8: 75 | AA8: =IF(V8>Z8,"Yes","No") -> No | AB8: =V8-Z8 -> -21.72864 | AC8: Yes | AD8: No | AE8: INTERNAL-0000 | AF8: =IF(AG8="Rejected",0,IF(R8="Corporate Card",0,V8)) -> 0 | AG8: Approved | AH8: 45667 | AI8: 45672 | AJ8: 45686 | AK8: =IF(AJ8="","",AJ8-AH8) -> 19
A9: EXP-00008 | B9: EMP-1103 | C9: Rohit Malhotra | D9: Sales | E9: Account Executive | F9: Ananya Sengupta | G9: TRP-2025-061 | H9: Client Meeting | I9: London | J9: United Kingdom | K9: 45658 | L9: 45661 | M9: 45659 | N9: 2025-01 | O9: Meals - Lunch | P9: Individual meal | Q9: Local Bistro | R9: Personal Card (Reimbursable) | S9: GBP | T9: 10.06 | U9: 1.272 | V9: =T9*U9 -> 12.79632 | W9: 0.2 | X9: =V9-(V9/(1+W9)) -> 2.13272 | Y9: =V9-X9 -> 10.6636 | Z9: 35 | AA9: =IF(V9>Z9,"Yes","No") -> No | AB9: =V9-Z9 -> -22.20368 | AC9: Yes | AD9: No | AE9: INTERNAL-0000 | AF9: =IF(AG9="Rejected",0,IF(R9="Corporate Card",0,V9)) -> 12.79632 | AG9: Approved | AH9: 45667 | AI9: 45672 | AJ9: 45686 | AK9: =IF(AJ9="","",AJ9-AH9) -> 19
A10: EXP-00009 | B10: EMP-1103 | C10: Rohit Malhotra | D10: Sales | E10: Account Executive | F10: Ananya Sengupta | G10: TRP-2025-061 | H10: Client Meeting | I10: London | J10: United Kingdom | K10: 45658 | L10: 45661 | M10: 45660 | N10: 2025-01 | O10: Ground Transport - Taxi | P10: Airport / client site transfer | Q10: Grab | R10: Corporate Card | S10: GBP | T10: 40.46 | U10: 1.272 | V10: =T10*U10 -> 51.46512 | W10: 0.2 | X10: =V10-(V10/(1+W10)) -> 8.57752 | Y10: =V10-X10 -> 42.8876 | Z10: 60 | AA10: =IF(V10>Z10,"Yes","No") -> No | AB10: =V10-Z10 -> -8.53488 | AC10: Yes | AD10: No | AE10: INTERNAL-0000 | AF10: =IF(AG10="Rejected",0,IF(R10="Corporate Card",0,V10)) -> 0 | AG10: Approved | AH10: 45667 | AI10: 45672 | AJ10: 45686 | AK10: =IF(AJ10="","",AJ10-AH10) -> 19
A11: EXP-00010 | B11: EMP-1103 | C11: Rohit Malhotra | D11: Sales | E11: Account Executive | F11: Ananya Sengupta | G11: TRP-2025-061 | H11: Client Meeting | I11: London | J11: United Kingdom | K11: 45658 | L11: 45661 | M11: 45660 | N11: 2025-01 | O11: Meals - Breakfast | P11: Individual meal | Q11: Hotel Restaurant | R11: Corporate Card | S11: GBP | T11: 18.83 | U11: 1.272 | V11: =T11*U11 -> 23.95176 | W11: 0.2 | X11: =V11-(V11/(1+W11)) -> 3.99196 | Y11: =V11-X11 -> 19.9598 | Z11: 25 | AA11: =IF(V11>Z11,"Yes","No") -> No | AB11: =V11-Z11 -> -1.04824 | AC11: Yes | AD11: No | AE11: INTERNAL-0000 | AF11: =IF(AG11="Rejected",0,IF(R11="Corporate Card",0,V11)) -> 0 | AG11: Approved | AH11: 45667 | AI11: 45672 | AJ11: 45686 | AK11: =IF(AJ11="","",AJ11-AH11) -> 19
A12: EXP-00011 | B12: EMP-1103 | C12: Rohit Malhotra | D12: Sales | E12: Account Executive | F12: Ananya Sengupta | G12: TRP-2025-061 | H12: Client Meeting | I12: London | J12: United Kingdom | K12: 45658 | L12: 45661 | M12: 45660 | N12: 2025-01 | O12: Meals - Dinner | P12: Party of 4 | Q12: The Grill House | R12: Personal Card (Reimbursable) | S12: GBP | T12: 38.94 | U12: 1.272 | V12: =T12*U12 -> 49.53168 | W12: 0.2 | X12: =V12-(V12/(1+W12)) -> 8.25528 | Y12: =V12-X12 -> 41.2764 | Z12: 75 | AA12: =IF(V12>Z12,"Yes","No") -> No | AB12: =V12-Z12 -> -25.46832 | AC12: Yes | AD12: No | AE12: INTERNAL-0000 | AF12: =IF(AG12="Rejected",0,IF(R12="Corporate Card",0,V12)) -> 49.53168 | AG12: Approved | AH12: 45667 | AI12: 45672 | AJ12: 45686 | AK12: =IF(AJ12="","",AJ12-AH12) -> 19
A13: EXP-00012 | B13: EMP-1103 | C13: Rohit Malhotra | D13: Sales | E13: Account Executive | F13: Ananya Sengupta | G13: TRP-2025-061 | H13: Client Meeting | I13: London | J13: United Kingdom | K13: 45658 | L13: 45661 | M13: 45660 | N13: 2025-01 | O13: Meals - Lunch | P13: Individual meal | Q13: Sweetgreen | R13: Corporate Card | S13: GBP | T13: 35.53 | U13: 1.272 | V13: =T13*U13 -> 45.19416 | W13: 0.2 | X13: =V13-(V13/(1+W13)) -> 7.53236 | Y13: =V13-X13 -> 37.6618 | Z13: 35 | AA13: =IF(V13>Z13,"Yes","No") -> Yes | AB13: =V13-Z13 -> 10.19416 | AC13: Yes | AD13: No | AE13: INTERNAL-0000 | AF13: =IF(AG13="Rejected",0,IF(R13="Corporate Card",0,V13)) -> 0 | AG13: Approved | AH13: 45667 | AI13: 45672 | AJ13: 45686 | AK13: =IF(AJ13="","",AJ13-AH13) -> 19
... A16: EXP-00015 | B16: EMP-1103 | C16: Rohit Malhotra | D16: Sales | E16: Account Executive | F16: Ananya Sengupta | G16: TRP-2025-061 | H16: Client Meeting | I16: London | J16: United Kingdom | K16: 45658 | L16: 45661 | M16: 45661 | N16: 2025-01 | O16: Meals - Lunch | P16: Individual meal | Q16: Local Bistro | R16: Personal Card (Reimbursable) | S16: GBP | T16: 24.13 | U16: 1.272 | V16: =T16*U16 -> 30.69336 | W16: 0.2 | X16: =V16-(V16/(1+W16)) -> 5.11556 | Y16: =V16-X16 -> 25.5778 | Z16: 35 | AA16: =IF(V16>Z16,"Yes","No") -> No | AB16: =V16-Z16 -> -4.30664 | AC16: No | AD16: No | AE16: INTERNAL-0000 | AF16: =IF(AG16="Rejected",0,IF(R16="Corporate Card",0,V16)) -> 30.69336 | AG16: Approved | AH16: 45667 | AI16: 45672 | AJ16: 45686 | AK16: =IF(AJ16="","",AJ16-AH16) -> 19
A17: EXP-00016 | B17: EMP-1229 | C17: Samuel Adeyemi | D17: Field Engineering | E17: Field Engineer | F17: Tomas Kovac | G17: TRP-2025-116 | H17: Client Meeting | I17: Sao Paulo | J17: Brazil | K17: 45661 | L17: 45668 | M17: 45661 | N17: 2025-01 | O17: Airfare | P17: Round trip HQ - Sao Paulo, economy | Q17: Delta Air Lines | R17: Corporate Card | S17: BRL | T17: 6071.89 | U17: 0.181 | V17: =T17*U17 -> 1099.0121 | W17: 0 | X17: =V17-(V17/(1+W17)) -> 0 | Y17: =V17-X17 -> 1099.0121 | Z17: 1400 | AA17: =IF(V17>Z17,"Yes","No") -> No | AB17: =V17-Z17 -> -300.98791 | AC17: Yes | AD17: Yes | AE17: BLUEPEAK-7702 | AF17: =IF(AG17="Rejected",0,IF(R17="Corporate Card",0,V17)) -> 0 | AG17: Pending Approval | AH17: 45677 | AK17: =IF(AJ17="","",AJ17-AH17)
A18: EXP-00017 | B18: EMP-1229 | C18: Samuel Adeyemi | D18: Field Engineering | E18: Field Engineer | F18: Tomas Kovac | G18: TRP-2025-116 | H18: Client Meeting | I18: Sao Paulo | J18: Brazil | K18: 45661 | L18: 45668 | M18: 45661 | N18: 2025-01 | O18: Baggage & Excess Fees | P18: Checked demo equipment | Q18: Emirates | R18: Personal Card (Reimbursable) | S18: BRL | T18: 341.6 | U18: 0.181 | V18: =T18*U18 -> 61.8296 | W18: 0 | X18: =V18-(V18/(1+W18)) -> 0 | Y18: =V18-X18 -> 61.8296 | Z18: 120 | AA18: =IF(V18>Z18,"Yes","No") -> No | AB18: =V18-Z18 -> -58.1704 | AC18: Yes | AD18: Yes | AE18: BLUEPEAK-7702 | AF18: =IF(AG18="Rejected",0,IF(R18="Corporate Card",0,V18)) -> 61.8296 | AG18: Pending Approval | AH18: 45677 | AK18: =IF(AJ18="","",AJ18-AH18)
A19: EXP-00018 | B19: EMP-1229 | C19: Samuel Adeyemi | D19: Field Engineering | E19: Field Engineer | F19: Tomas Kovac | G19: TRP-2025-116 | H19: Client Meeting | I19: Sao Paulo | J19: Brazil | K19: 45661 | L19: 45668 | M19: 45661 | N19: 2025-01 | O19: Ground Transport - Taxi | P19: Airport / client site transfer | Q19: Grab | R19: Corporate Card | S19: BRL | T19: 254.57 | U19: 0.181 | V19: =T19*U19 -> 46.07717 | W19: 0.17 | X19: =V19-(V19/(1+W19)) -> 6.6949734 | Y19: =V19-X19 -> 39.382197 | Z19: 60 | AA19: =IF(V19>Z19,"Yes","No") -> No | AB19: =V19-Z19 -> -13.92283 | AC19: Yes | AD19: Yes | AE19: BLUEPEAK-7702 | AF19: =IF(AG19="Rejected",0,IF(R19="Corporate Card",0,V19)) -> 0 | AG19: Pending Approval | AH19: 45677 | AK19: =IF(AJ19="","",AJ19-AH19)
A20: EXP-00019 | B20: EMP-1229 | C20: Samuel Adeyemi | D20: Field Engineering | E20: Field Engineer | F20: Tomas Kovac | G20: TRP-2025-116 | H20: Client Meeting | I20: Sao Paulo | J20: Brazil | K20: 45661 | L20: 45668 | M20: 45661 | N20: 2025-01 | O20: Meals - Dinner | P20: Party of 2 | Q20: Osteria Vela | R20: Corporate Card | S20: BRL | T20: 324.01 | U20: 0.181 | V20: =T20*U20 -> 58.64581 | W20: 0.17 | X20: =V20-(V20/(1+W20)) -> 8.5211861 | Y20: =V20-X20 -> 50.124624 | Z20: 75 | AA20: =IF(V20>Z20,"Yes","No") -> No | AB20: =V20-Z20 -> -16.35419 | AC20: No | AD20: Yes | AE20: BLUEPEAK-7702 | AF20: =IF(AG20="Rejected",0,IF(R20="Corporate Card",0,V20)) -> 0 | AG20: Pending Approval | AH20: 45677 | AK20: =IF(AJ20="","",AJ20-AH20)
A21: EXP-00020 | B21: EMP-1229 | C21: Samuel Adeyemi | D21: Field Engineering | E21: Field Engineer | F21: Tomas Kovac | G21: TRP-2025-116 | H21: Client Meeting | I21: Sao Paulo | J21: Brazil | K21: 45661 | L21: 45668 | M21: 45661 | N21: 2025-01 | O21: Meals - Lunch | P21: Individual meal | Q21: Pret A Manger | R21: Personal Card (Reimbursable) | S21: BRL | T21: 88.32 | U21: 0.181 | V21: =T21*U21 -> 15.98592 | W21: 0.17 | X21: =V21-(V21/(1+W21)) -> 2.3227405 | Y21: =V21-X21 -> 13.663179 | Z21: 35 | AA21: =IF(V21>Z21,"Yes","No") -> No | AB21: =V21-Z21 -> -19.01408 | AC21: Yes | AD21: Yes | AE21: BLUEPEAK-7702 | AF21: =IF(AG21="Rejected",0,IF(R21="Corporate Card",0,V21)) -> 15.98592 | AG21: Pending Approval | AH21: 45677 | AK21: =IF(AJ21="","",AJ21-AH21)
A22: EXP-00021 | B22: EMP-1204 | C22: Priya Nair | D22: Field Engineering | E22: Senior Field Engineer | F22: Tomas Kovac | G22: TRP-2025-109 | H22: Product Launch Event | I22: Paris | J22: France | K22: 45662 | L22: 45665 | M22: 45662 | N22: 2025-01 | O22: Airfare | P22: Round trip HQ - Paris, economy | Q22: Singapore Airlines | R22: Corporate Card | S22: EUR | T22: 1221.22 | U22: 1.085 | V22: =T22*U22 -> 1325.0237 | W22: 0 | X22: =V22-(V22/(1+W22)) -> 0 | Y22: =V22-X22 -> 1325.0237 | Z22: 1400 | AA22: =IF(V22>Z22,"Yes","No") -> No | AB22: =V22-Z22 -> -74.9763 | AC22: Yes | AD22: No | AE22: INTERNAL-0000 | AF22: =IF(AG22="Rejected",0,IF(R22="Corporate Card",0,V22)) -> 0 | AG22: Approved | AH22: 45670 | AI22: 45678 | AJ22: 45685 | AK22: =IF(AJ22="","",AJ22-AH22) -> 15
A23: EXP-00022 | B23: EMP-1204 | C23: Priya Nair | D23: Field Engineering | E23: Senior Field Engineer | F23: Tomas Kovac | G23: TRP-2025-109 | H23: Product Launch Event | I23: Paris | J23: France | K23: 45662 | L23: 45665 | M23: 45662 | N23: 2025-01 | O23: Conference / Event Fee | P23: Delegate registration | Q23: SensorTech Summit | R23: Corporate Card | S23: EUR | T23: 1058.38 | U23: 1.085 | V23: =T23*U23 -> 1148.3423 | W23: 0 | X23: =V23-(V23/(1+W23)) -> 0 | Y23: =V23-X23 -> 1148.3423 | Z23: 1200 | AA23: =IF(V23>Z23,"Yes","No") -> No | AB23: =V23-Z23 -> -51.6577 | AC23: Yes | AD23: No | AE23: INTERNAL-0000 | AF23: =IF(AG23="Rejected",0,IF(R23="Corporate Card",0,V23)) -> 0 | AG23: Approved | AH23: 45670 | AI23: 45678 | AJ23: 45685 | AK23: =IF(AJ23="","",AJ23-AH23) -> 15
A24: EXP-00023 | B24: EMP-1204 | C24: Priya Nair | D24: Field Engineering | E24: Senior Field Engineer | F24: Tomas Kovac | G24: TRP-2025-109 | H24: Product Launch Event | I24: Paris | J24: France | K24: 45662 | L24: 45665 | M24: 45662 | N24: 2025-01 | O24: Ground Transport - Taxi | P24: Airport / client site transfer | Q24: Ola Cabs | R24: Corporate Card | S24: EUR | T24: 33.06 | U24: 1.085 | V24: =T24*U24 -> 35.8701 | W24: 0.19 | X24: =V24-(V24/(1+W24)) -> 5.7271588 | Y24: =V24-X24 -> 30.142941 | Z24: 60 | AA24: =IF(V24>Z24,"Yes","No") -> No | AB24: =V24-Z24 -> -24.1299 | AC24: Yes | AD24: No | AE24: INTERNAL-0000 | AF24: =IF(AG24="Rejected",0,IF(R24="Corporate Card",0,V24)) -> 0 | AG24: Approved | AH24: 45670 | AI24: 45678 | AJ24: 45685 | AK24: =IF(AJ24="","",AJ24-AH24) -> 15
A25: EXP-00024 | B25: EMP-1204 | C25: Priya Nair | D25: Field Engineering | E25: Senior Field Engineer | F25: Tomas Kovac | G25: TRP-2025-109 | H25: Product Launch Event | I25: Paris | J25: France | K25: 45662 | L25: 45665 | M25: 45662 | N25: 2025-01 | O25: Meals - Breakfast | P25: Individual meal | Q25: Starbucks | R25: Corporate Card | S25: EUR | T25: 21.52 | U25: 1.085 | V25: =T25*U25 -> 23.3492 | W25: 0.19 | X25: =V25-(V25/(1+W25)) -> 3.7280235 | Y25: =V25-X25 -> 19.621176 | Z25: 25 | AA25: =IF(V25>Z25,"Yes","No") -> No | AB25: =V25-Z25 -> -1.6508 | AC25: Yes | AD25: No | AE25: INTERNAL-0000 | AF25: =IF(AG25="Rejected",0,IF(R25="Corporate Card",0,V25)) -> 0 | AG25: Approved | AH25: 45670 | AI25: 45678 | AJ25: 45685 | AK25: =IF(AJ25="","",AJ25-AH25) -> 15
A26: EXP-00025 | B26: EMP-1204 | C26: Priya Nair | D26: Field Engineering | E26: Senior Field Engineer | F26: Tomas Kovac | G26: TRP-2025-109 | H26: Product Launch Event | I26: Paris | J26: France | K26: 45662 | L26: 45665 | M26: 45662 | N26: 2025-01 | O26: Meals - Dinner | P26: Party of 4 | Q26: Osteria Vela | R26: Corporate Card | S26: EUR | T26: 33.22 | U26: 1.085 | V26: =T26*U26 -> 36.0437 | W26: 0.19 | X26: =V26-(V26/(1+W26)) -> 5.7548765 | Y26: =V26-X26 -> 30.288824 | Z26: 75 | AA26: =IF(V26>Z26,"Yes","No") -> No | AB26: =V26-Z26 -> -38.9563 | AC26: Yes | AD26: No | AE26: INTERNAL-0000 | AF26: =IF(AG26="Rejected",0,IF(R26="Corporate Card",0,V26)) -> 0 | AG26: Approved | AH26: 45670 | AI26: 45678 | AJ26: 45685 | AK26: =IF(AJ26="","",AJ26-AH26) -> 15
A27: EXP-00026 | B27: EMP-1204 | C27: Priya Nair | D27: Field Engineering | E27: Senior Field Engineer | F27: Tomas Kovac | G27: TRP-2025-109 | H27: Product Launch Event | I27: Paris | J27: France | K27: 45662 | L27: 45665 | M27: 45662 | N27: 2025-01 | O27: Meals - Lunch | P27: Individual meal | Q27: Local Bistro | R27: Corporate Card | S27: EUR | T27: 40.7 | U27: 1.085 | V27: =T27*U27 -> 44.1595 | W27: 0.19 | X27: =V27-(V27/(1+W27)) -> 7.0506765 | Y27: =V27-X27 -> 37.108824 | Z27: 35 | AA27: =IF(V27>Z27,"Yes","No") -> Yes | AB27: =V27-Z27 -> 9.1595 | AC27: Yes | AD27: No | AE27: INTERNAL-0000 | AF27: =IF(AG27="Rejected",0,IF(R27="Corporate Card",0,V27)) -> 0 | AG27: Approved | AH27: 45670 | AI27: 45678 | AJ27: 45685 | AK27: =IF(AJ27="","",AJ27-AH27) -> 15
A28: EXP-00027 | B28: EMP-1229 | C28: Samuel Adeyemi | D28: Field Engineering | E28: Field Engineer | F28: Tomas Kovac | G28: TRP-2025-116 | H28: Client Meeting | I28: Sao Paulo | J28: Brazil | K28: 45661 | L28: 45668 | M28: 45662 | N28: 2025-01 | O28: Hotel / Lodging | P28: 7 night(s) @ standard rate | Q28: Premier Inn | R28: Corporate Card | S28: BRL | T28: 9806.12 | U28: 0.181 | V28: =T28*U28 -> 1774.9077 | W28: 0.17 | X28: =V28-(V28/(1+W28)) -> 257.89257 | Y28: =V28-X28 -> 1517.0151 | Z28: 1960 | AA28: =IF(V28>Z28,"Yes","No") -> No | AB28: =V28-Z28 -> -185.09228 | AC28: Yes | AD28: Yes | AE28: BLUEPEAK-7702 | AF28: =IF(AG28="Rejected",0,IF(R28="Corporate Card",0,V28)) -> 0 | AG28: Pending Approval | AH28: 45677 | AK28: =IF(AJ28="","",AJ28-AH28)
A29: EXP-00028 | B29: EMP-1229 | C29: Samuel Adeyemi | D29: Field Engineering | E29: Field Engineer | F29: Tomas Kovac | G29: TRP-2025-116 | H29: Client Meeting | I29: Sao Paulo | J29: Brazil | K29: 45661 | L29: 45668 | M29: 45662 | N29: 2025-01 | O29: Internet / Roaming | P29: International data pack | Q29: Vodafone Roaming | R29: Corporate Card | S29: BRL | T29: 303.2 | U29: 0.181 | V29: =T29*U29 -> 54.8792 | W29: 0.17 | X29: =V29-(V29/(1+W29)) -> 7.9739009 | Y29: =V29-X29 -> 46.905299 | Z29: 55 | AA29: =IF(V29>Z29,"Yes","No") -> No | AB29: =V29-Z29 -> -0.1208 | AC29: Yes | AD29: Yes | AE29: BLUEPEAK-7702 | AF29: =IF(AG29="Rejected",0,IF(R29="Corporate Card",0,V29)) -> 0 | AG29: Pending Approval | AH29: 45677 | AK29: =IF(AJ29="","",AJ29-AH29)
A30: EXP-00029 | B30: EMP-1229 | C30: Samuel Adeyemi | D30: Field Engineering | E30: Field Engineer | F30: Tomas Kovac | G30: TRP-2025-116 | H30: Client Meeting | I30: Sao Paulo | J30: Brazil | K30: 45661 | L30: 45668 | M30: 45662 | N30: 2025-01 | O30: Meals - Breakfast | P30: Individual meal | Q30: Local Bakery | R30: Corporate Card | S30: BRL | T30: 55.76 | U30: 0.181 | V30: =T30*U30 -> 10.09256 | W30: 0.17 | X30: =V30-(V30/(1+W30)) -> 1.4664403 | Y30: =V30-X30 -> 8.6261197 | Z30: 25 | AA30: =IF(V30>Z30,"Yes","No") -> No | AB30: =V30-Z30 -> -14.90744 | AC30: Yes | AD30: Yes | AE30: BLUEPEAK-7702 | AF30: =IF(AG30="Rejected",0,IF(R30="Corporate Card",0,V30)) -> 0 | AG30: Pending Approval | AH30: 45677 | AK30: =IF(AJ30="","",AJ30-AH30)
A31: EXP-00030 | B31: EMP-1229 | C31: Samuel Adeyemi | D31: Field Engineering | E31: Field Engineer | F31: Tomas Kovac | G31: TRP-2025-116 | H31: Client Meeting | I31: Sao Paulo | J31: Brazil | K31: 45661 | L31: 45668 | M31: 45662 | N31: 2025-01 | O31: Meals - Dinner | P31: Party of 4 | Q31: The Grill House | R31: Cash (Reimbursable) | S31: BRL | T31: 206.42 | U31: 0.181 | V31: =T31*U31 -> 37.36202 | W31: 0.17 | X31: =V31-(V31/(1+W31)) -> 5.4286696 | Y31: =V31-X31 -> 31.93335 | Z31: 75 | AA31: =IF(V31>Z31,"Yes","No") -> No | AB31: =V31-Z31 -> -37.63798 | AC31: No | AD31: Yes | AE31: BLUEPEAK-7702 | AF31: =IF(AG31="Rejected",0,IF(R31="Corporate Card",0,V31)) -> 37.36202 | AG31: Pending Approval | AH31: 45677 | AK31: =IF(AJ31="","",AJ31-AH31)
A32: EXP-00031 | B32: EMP-1229 | C32: Samuel Adeyemi | D32: Field Engineering | E32: Field Engineer | F32: Tomas Kovac | G32: TRP-2025-116 | H32: Client Meeting | I32: Sao Paulo | J32: Brazil | K32: 45661 | L32: 45668 | M32: 45662 | N32: 2025-01 | O32: Meals - Lunch | P32: Individual meal | Q32: Food Court | R32: Corporate Card | S32: BRL | T32: 87.67 | U32: 0.181 | V32: =T32*U32 -> 15.86827 | W32: 0.17 | X32: =V32-(V32/(1+W32)) -> 2.3056461 | Y32: =V32-X32 -> 13.562624 | Z32: 35 | AA32: =IF(V32>Z32,"Yes","No") -> No | AB32: =V32-Z32 -> -19.13173 | AC32: Yes | AD32: Yes | AE32: BLUEPEAK-7702 | AF32: =IF(AG32="Rejected",0,IF(R32="Corporate Card",0,V32)) -> 0 | AG32: Pending Approval | AH32: 45677 | AK32: =IF(AJ32="","",AJ32-AH32)
A33: EXP-00032 | B33: EMP-1204 | C33: Priya Nair | D33: Field Engineering | E33: Senior Field Engineer | F33: Tomas Kovac | G33: TRP-2025-109 | H33: Product Launch Event | I33: Paris | J33: France | K33: 45662 | L33: 45665 | M33: 45663 | N33: 2025-01 | O33: Ground Transport - Taxi | P33: Airport / client site transfer | Q33: Grab | R33: Corporate Card | S33: EUR | T33: 26.45 | U33: 1.085 | V33: =T33*U33 -> 28.69825 | W33: 0.19 | X33: =V33-(V33/(1+W33)) -> 4.5820735 | Y33: =V33-X33 -> 24.116176 | Z33: 60 | AA33: =IF(V33>Z33,"Yes","No") -> No | AB33: =V33-Z33 -> -31.30175 | AC33: Yes | AD33: No | AE33: INTERNAL-0000 | AF33: =IF(AG33="Rejected",0,IF(R33="Corporate Card",0,V33)) -> 0 | AG33: Approved | AH33: 45670 | AI33: 45678 | AJ33: 45685 | AK33: =IF(AJ33="","",AJ33-AH33) -> 15
A34: EXP-00033 | B34: EMP-1204 | C34: Priya Nair | D34: Field Engineering | E34: Senior Field Engineer | F34: Tomas Kovac | G34: TRP-2025-109 | H34: Product Launch Event | I34: Paris | J34: France | K34: 45662 | L34: 45665 | M34: 45663 | N34: 2025-01 | O34: Hotel / Lodging | P34: 3 night(s) @ standard rate | Q34: Hilton Garden Inn | R34: Cash (Reimbursable) | S34: EUR | T34: 489.02 | U34: 1.085 | V34: =T34*U34 -> 530.5867 | W34: 0.19 | X34: =V34-(V34/(1+W34)) -> 84.715524 | Y34: =V34-X34 -> 445.87118 | Z34: 840 | AA34: =IF(V34>Z34,"Yes","No") -> No | AB34: =V34-Z34 -> -309.4133 | AC34: Yes | AD34: No | AE34: INTERNAL-0000 | AF34: =IF(AG34="Rejected",0,IF(R34="Corporate Card",0,V34)) -> 530.5867 | AG34: Approved | AH34: 45670 | AI34: 45678 | AJ34: 45685 | AK34: =IF(AJ34="","",AJ34-AH34) -> 15
A35: EXP-00034 | B35: EMP-1204 | C35: Priya Nair | D35: Field Engineering | E35: Senior Field Engineer | F35: Tomas Kovac | G35: TRP-2025-109 | H35: Product Launch Event | I35: Paris | J35: France | K35: 45662 | L35: 45665 | M35: 45663 | N35: 2025-01 | O35: Meals - Dinner | P35: Party of 2 | Q35: The Grill House | R35: Personal Card (Reimbursable) | S35: EUR | T35: 48.81 | U35: 1.085 | V35: =T35*U35 -> 52.95885 | W35: 0.19 | X35: =V35-(V35/(1+W35)) -> 8.4556147 | Y35: =V35-X35 -> 44.503235 | Z35: 75 | AA35: =IF(V35>Z35,"Yes","No") -> No | AB35: =V35-Z35 -> -22.04115 | AC35: No | AD35: No | AE35: INTERNAL-0000 | AF35: =IF(AG35="Rejected",0,IF(R35="Corporate Card",0,V35)) -> 52.95885 | AG35: Approved | AH35: 45670 | AI35: 45678 | AJ35: 45685 | AK35: =IF(AJ35="","",AJ35-AH35) -> 15
A36: EXP-00035 | B36: EMP-1204 | C36: Priya Nair | D36: Field Engineering | E36: Senior Field Engineer | F36: Tomas Kovac | G36: TRP-2025-109 | H36: Product Launch Event | I36: Paris | J36: France | K36: 45662 | L36: 45665 | M36: 45663 | N36: 2025-01 | O36: Meals - Lunch | P36: Individual meal | Q36: Food Court | R36: Corporate Card | S36: EUR | T36: 29.38 | U36: 1.085 | V36: =T36*U36 -> 31.8773 | W36: 0.19 | X36: =V36-(V36/(1+W36)) -> 5.0896529 | Y36: =V36-X36 -> 26.787647 | Z36: 35 | AA36: =IF(V36>Z36,"Yes","No") -> No | AB36: =V36-Z36 -> -3.1227 | AC36: Yes | AD36: No | AE36: INTERNAL-0000 | AF36: =IF(AG36="Rejected",0,IF(R36="Corporate Card",0,V36)) -> 0 | AG36: Approved | AH36: 45670 | AI36: 45678 | AJ36: 45685 | AK36: =IF(AJ36="","",AJ36-AH36) -> 15
A37: EXP-00036 | B37: EMP-1229 | C37: Samuel Adeyemi | D37: Field Engineering | E37: Field Engineer | F37: Tomas Kovac | G37: TRP-2025-116 | H37: Client Meeting | I37: Sao Paulo | J37: Brazil | K37: 45661 | L37: 45668 | M37: 45663 | N37: 2025-01 | O37: Ground Transport - Taxi | P37: Airport / client site transfer | Q37: Lyft | R37: Corporate Card | S37: BRL | T37: 237.13 | U37: 0.181 | V37: =T37*U37 -> 42.92053 | W37: 0.17 | X37: =V37-(V37/(1+W37)) -> 6.2363163 | Y37: =V37-X37 -> 36.684214 | Z37: 60 | AA37: =IF(V37>Z37,"Yes","No") -> No | AB37: =V37-Z37 -> -17.07947 | AC37: Yes | AD37: Yes | AE37: BLUEPEAK-7702 | AF37: =IF(AG37="Rejected",0,IF(R37="Corporate Card",0,V37)) -> 0 | AG37: Pending Approval | AH37: 45677 | AK37: =IF(AJ37="","",AJ37-AH37)
A38: EXP-00037 | B38: EMP-1229 | C38: Samuel Adeyemi | D38: Field Engineering | E38: Field Engineer | F38: Tomas Kovac | G38: TRP-2025-116 | H38: Client Meeting | I38: Sao Paulo | J38: Brazil | K38: 45661 | L38: 45668 | M38: 45663 | N38: 2025-01 | O38: Meals - Breakfast | P38: Individual meal | Q38: Cafe Nero | R38: Corporate Card | S38: BRL | T38: 91.17 | U38: 0.181 | V38: =T38*U38 -> 16.50177 | W38: 0.17 | X38: =V38-(V38/(1+W38)) -> 2.3976931 | Y38: =V38-X38 -> 14.104077 | Z38: 25 | AA38: =IF(V38>Z38,"Yes","No") -> No | AB38: =V38-Z38 -> -8.49823 | AC38: Yes | AD38: Yes | AE38: BLUEPEAK-7702 | AF38: =IF(AG38="Rejected",0,IF(R38="Corporate Card",0,V38)) -> 0 | AG38: Pending Approval | AH38: 45677 | AK38: =IF(AJ38="","",AJ38-AH38)
A39: EXP-00038 | B39: EMP-1229 | C39: Samuel Adeyemi | D39: Field Engineering | E39: Field Engineer | F39: Tomas Kovac | G39: TRP-2025-116 | H39: Client Meeting | I39: Sao Paulo | J39: Brazil | K39: 45661 | L39: 45668 | M39: 45663 | N39: 2025-01 | O39: Meals - Dinner | P39: Party of 2 | Q39: Sakura Izakaya | R39: Cash (Reimbursable) | S39: BRL | T39: 297.49 | U39: 0.181 | V39: =T39*U39 -> 53.84569 | W39: 0.17 | X39: =V39-(V39/(1+W39)) -> 7.8237327 | Y39: =V39-X39 -> 46.021957 | Z39: 75 | AA39: =IF(V39>Z39,"Yes","No") -> No | AB39: =V39-Z39 -> -21.15431 | AC39: Yes | AD39: Yes | AE39: BLUEPEAK-7702 | AF39: =IF(AG39="Rejected",0,IF(R39="Corporate Card",0,V39)) -> 53.84569 | AG39: Pending Approval | AH39: 45677 | AK39: =IF(AJ39="","",AJ39-AH39)
A40: EXP-00039 | B40: EMP-1229 | C40: Samuel Adeyemi | D40: Field Engineering | E40: Field Engineer | F40: Tomas Kovac | G40: TRP-2025-116 | H40: Client Meeting | I40: Sao Paulo | J40: Brazil | K40: 45661 | L40: 45668 | M40: 45663 | N40: 2025-01 | O40: Meals - Lunch | P40: Individual meal | Q40: Food Court | R40: Personal Card (Reimbursable) | S40: BRL | T40: 88.32 | U40: 0.181 | V40: =T40*U40 -> 15.98592 | W40: 0.17 | X40: =V40-(V40/(1+W40)) -> 2.3227405 | Y40: =V40-X40 -> 13.663179 | Z40: 35 | AA40: =IF(V40>Z40,"Yes","No") -> No | AB40: =V40-Z40 -> -19.01408 | AC40: Yes | AD40: Yes | AE40: BLUEPEAK-7702 | AF40: =IF(AG40="Rejected",0,IF(R40="Corporate Card",0,V40)) -> 15.98592 | AG40: Pending Approval | AH40: 45677 | AK40: =IF(AJ40="","",AJ40-AH40)
A41: EXP-00040 | B41: EMP-1204 | C41: Priya Nair | D41: Field Engineering | E41: Senior Field Engineer | F41: Tomas Kovac | G41: TRP-2025-109 | H41: Product Launch Event | I41: Paris | J41: France | K41: 45662 | L41: 45665 | M41: 45664 | N41: 2025-01 | O41: Meals - Breakfast | P41: Individual meal | Q41: Local Bakery | R41: Personal Card (Reimbursable) | S41: EUR | T41: 16.25 | U41: 1.085 | V41: =T41*U41 -> 17.63125 | W41: 0.19 | X41: =V41-(V41/(1+W41)) -> 2.8150735 | Y41: =V41-X41 -> 14.816176 | Z41: 25 | AA41: =IF(V41>Z41,"Yes","No") -> No | AB41: =V41-Z41 -> -7.36875 | AC41: Yes | AD41: No | AE41: INTERNAL-0000 | AF41: =IF(AG41="Rejected",0,IF(R41="Corporate Card",0,V41)) -> 17.63125 | AG41: Approved | AH41: 45670 | AI41: 45678 | AJ41: 45685 | AK41: =IF(AJ41="","",AJ41-AH41) -> 15
A42: EXP-00041 | B42: EMP-1204 | C42: Priya Nair | D42: Field Engineering | E42: Senior Field Engineer | F42: Tomas Kovac | G42: TRP-2025-109 | H42: Product Launch Event | I42: Paris | J42: France | K42: 45662 | L42: 45665 | M42: 45664 | N42: 2025-01 | O42: Meals - Dinner | P42: Party of 1 | Q42: Sakura Izakaya | R42: Corporate Card | S42: EUR | T42: 63.82 | U42: 1.085 | V42: =T42*U42 -> 69.2447 | W42: 0.19 | X42: =V42-(V42/(1+W42)) -> 11.055876 | Y42: =V42-X42 -> 58.188824 | Z42: 75 | AA42: =IF(V42>Z42,"Yes","No") -> No | AB42: =V42-Z42 -> -5.7553 | AC42: Yes | AD42: No | AE42: INTERNAL-0000 | AF42: =IF(AG42="Rejected",0,IF(R42="Corporate Card",0,V42)) -> 0 | AG42: Approved | AH42: 45670 | AI42: 45678 | AJ42: 45685 | AK42: =IF(AJ42="","",AJ42-AH42) -> 15
...

Sheet Trip Summary
A1: Helios Instruments Pvt. Ltd. — Business Travel: Trip Summary, 2025
A3: Trip ID | B3: Employee Name | C3: Department | D3: Destination City | E3: Country | F3: Trip Purpose | G3: Trip Start | H3: Trip End | I3: Duration (days) | J3: Line Items | K3: Total Spend (USD) | L3: Cost per Day (USD) | M3: Items Over Policy | N3: Reimbursable (USD) | O3: Client / Project | P3: Billable | Q3: Approval Status
A4: TRP-2025-001 | B4: Samuel Adeyemi | C4: Field Engineering | D4: London | E4: United Kingdom | F4: Contract Negotiation | G4: 45773 | H4: 45776 | I4: =H4-G4+1 -> 4 | J4: =COUNTIFS('Expense Details'!$G$2:$G$2955,$A4) -> 17 | K4: =SUMIFS('Expense Details'!$V$2:$V$2955,'Expense Details'!$G$2:$G$2955,$A4) -> 3530.0671 | L4: =IFERROR(K4/I4,0) -> 882.51678 | M4: =COUNTIFS('Expense Details'!$G$2:$G$2955,$A4,'Expense Details'!$AA$2:$AA$2955,"Yes") -> 1 | N4: =SUMIFS('Expense Details'!$AF$2:$AF$2955,'Expense Details'!$G$2:$G$2955,$A4) -> 3181.5391 | O4: BLUEPEAK-7702 | P4: Yes | Q4: Approved
A5: TRP-2025-002 | B5: Aisha Bello | C5: Operations | D5: Sao Paulo | E5: Brazil | F5: Internal Training | G5: 45713 | H5: 45714 | I5: =H5-G5+1 -> 2 | J5: =COUNTIFS('Expense Details'!$G$2:$G$2955,$A5) -> 10 | K5: =SUMIFS('Expense Details'!$V$2:$V$2955,'Expense Details'!$G$2:$G$2955,$A5) -> 3491.0103 | L5: =IFERROR(K5/I5,0) -> 1745.5052 | M5: =COUNTIFS('Expense Details'!$G$2:$G$2955,$A5,'Expense Details'!$AA$2:$AA$2955,"Yes") -> 5 | N5: =SUMIFS('Expense Details'!$AF$2:$AF$2955,'Expense Details'!$G$2:$G$2955,$A5) -> 85.29263 | O5: KAIZEN-6620 | P5: Yes | Q5: Approved
A6: TRP-2025-003 | B6: Sneha Iyer | C6: Customer Success | D6: Dubai | E6: UAE | F6: Product Launch Event | G6: 45843 | H6: 45846 | I6: =H6-G6+1 -> 4 | J6: =COUNTIFS('Expense Details'!$G$2:$G$2955,$A6) -> 15 | K6: =SUMIFS('Expense Details'!$V$2:$V$2955,'Expense Details'!$G$2:$G$2955,$A6) -> 2997.9713 | L6: =IFERROR(K6/I6,0) -> 749.49282 | M6: =COUNTIFS('Expense Details'!$G$2:$G$2955,$A6,'Expense Details'!$AA$2:$AA$2955,"Yes") -> 4 | N6: =SUMIFS('Expense Details'!$AF$2:$AF$2955,'Expense Details'!$G$2:$G$2955,$A6) -> 658.75361 | O6: KAIZEN-6620 | P6: Yes | Q6: Approved
A7: TRP-2025-004 | B7: Rohit Malhotra | C7: Sales | D7: Paris | E7: France | F7: Internal Training | G7: 45953 | H7: 45956 | I7: =H7-G7+1 -> 4 | J7: =COUNTIFS('Expense Details'!$G$2:$G$2955,$A7) -> 15 | K7: =SUMIFS('Expense Details'!$V$2:$V$2955,'Expense Details'!$G$2:$G$2955,$A7) -> 4850.0042 | L7: =IFERROR(K7/I7,0) -> 1212.5011 | M7: =COUNTIFS('Expense Details'!$G$2:$G$2955,$A7,'Expense Details'!$AA$2:$AA$2955,"Yes") -> 1 | N7: =SUMIFS('Expense Details'!$AF$2:$AF$2955,'Expense Details'!$G$2:$G$2955,$A7) -> 3811.9305 | O7: TATRA-3390 | P7: No | Q7: Approved
A8: TRP-2025-005 | B8: Fatima Al-Rashid | C8: Marketing | D8: Atlanta | E8: United States | F8: Sales Pitch / RFP Presentation | G8: 45684 | H8: 45691 | I8: =H8-G8+1 -> 8 | J8: =COUNTIFS('Expense Details'!$G$2:$G$2955,$A8) -> 29 | K8: =SUMIFS('Expense Details'!$V$2:$V$2955,'Expense Details'!$G$2:$G$2955,$A8) -> 4237.37 | L8: =IFERROR(K8/I8,0) -> 529.67125 | M8: =COUNTIFS('Expense Details'!$G$2:$G$2955,$A8,'Expense Details'!$AA$2:$AA$2955,"Yes") -> 3 | N8: =SUMIFS('Expense Details'!$AF$2:$AF$2955,'Expense Details'!$G$2:$G$2955,$A8) -> 1949.6 | O8: NORDIC-1180 | P8: Yes | Q8: Approved
A9: TRP-2025-006 | B9: Tomas Kovac | C9: Field Engineering | D9: Berlin | E9: Germany | F9: Trade Show / Conference | G9: 45798 | H9: 45804 | I9: =H9-G9+1 -> 7 | J9: =COUNTIFS('Expense Details'!$G$2:$G$2955,$A9) -> 25 | K9: =SUMIFS('Expense Details'!$V$2:$V$2955,'Expense Details'!$G$2:$G$2955,$A9) -> 5031.6658 | L9: =IFERROR(K9/I9,0) -> 718.8094 | M9: =COUNTIFS('Expense Details'!$G$2:$G$2955,$A9,'Expense Details'!$AA$2:$AA$2955,"Yes") -> 2 | N9: =SUMIFS('Expense Details'!$AF$2:$AF$2955,'Expense Details'!$G$2:$G$2955,$A9) -> 2701.65 | O9: MERIDIAN-4415 | P9: No | Q9: Approved
A10: TRP-2025-007 | B10: Clara Jensen | C10: Sales | D10: Atlanta | E10: United States | F10: Customer Site Installation | G10: 45927 | H10: 45930 | I10: =H10-G10+1 -> 4 | J10: =COUNTIFS('Expense Details'!$G$2:$G$2955,$A10) -> 14 | K10: =SUMIFS('Expense Details'!$V$2:$V$2955,'Expense Details'!$G$2:$G$2955,$A10) -> 2135.75 | L10: =IFERROR(K10/I10,0) -> 533.9375 | M10: =COUNTIFS('Expense Details'!$G$2:$G$2955,$A10,'Expense Details'!$AA$2:$AA$2955,"Yes") -> 0 | N10: =SUMIFS('Expense Details'!$AF$2:$AF$2955,'Expense Details'!$G$2:$G$2955,$A10) -> 151.88 | O10: BLUEPEAK-7702 | P10: No | Q10: Pending Approval
A11: TRP-2025-008 | B11: Oliver Brandt | C11: Marketing | D11: Bengaluru | E11: India | F11: Client Meeting | G11: 46003 | H11: 46005 | I11: =H11-G11+1 -> 3 | J11: =COUNTIFS('Expense Details'!$G$2:$G$2955,$A11) -> 13 | K11: =SUMIFS('Expense Details'!$V$2:$V$2955,'Expense Details'!$G$2:$G$2955,$A11) -> 1721.647 | L11: =IFERROR(K11/I11,0) -> 573.88233 | M11: =COUNTIFS('Expense Details'!$G$2:$G$2955,$A11,'Expense Details'!$AA$2:$AA$2955,"Yes") -> 1 | N11: =SUMIFS('Expense Details'!$AF$2:$AF$2955,'Expense Details'!$G$2:$G$2955,$A11) -> 516.80038 | O11: NORDIC-1180 | P11: Yes | Q11: Approved
A12: TRP-2025-009 | B12: Meera Krishnan | C12: Finance | D12: Munich | E12: Germany | F12: Product Launch Event | G12: 45871 | H12: 45877 | I12: =H12-G12+1 -> 7 | J12: =COUNTIFS('Expense Details'!$G$2:$G$2955,$A12) -> 27 | K12: =SUMIFS('Expense Details'!$V$2:$V$2955,'Expense Details'!$G$2:$G$2955,$A12) -> 7610.4178 | L12: =IFERROR(K12/I12,0) -> 1087.2025 | M12: =COUNTIFS('Expense Details'!$G$2:$G$2955,$A12,'Expense Details'!$AA$2:$AA$2955,"Yes") -> 3 | N12: =SUMIFS('Expense Details'!$AF$2:$AF$2955,'Expense Details'!$G$2:$G$2955,$A12) -> 2757.7553 | O12: MERIDIAN-4415 | P12: Yes | Q12: Approved
A13: TRP-2025-010 | B13: Oliver Brandt | C13: Marketing | D13: Munich | E13: Germany | F13: Internal Training | G13: 45816 | H13: 45820 | I13: =H13-G13+1 -> 5 | J13: =COUNTIFS('Expense Details'!$G$2:$G$2955,$A13) -> 17 | K13: =SUMIFS('Expense Details'!$V$2:$V$2955,'Expense Details'!$G$2:$G$2955,$A13) -> 3311.3874 | L13: =IFERROR(K13/I13,0) -> 662.27749 | M13: =COUNTIFS('Expense Details'!$G$2:$G$2955,$A13,'Expense Details'!$AA$2:$AA$2955,"Yes") -> 3 | N13: =SUMIFS('Expense Details'!$AF$2:$AF$2955,'Expense Details'!$G$2:$G$2955,$A13) -> 2080.238 | O13: INTERNAL-0000 | P13: No | Q13: Approved
A14: TRP-2025-011 | B14: Aisha Bello | C14: Operations | D14: Boston | E14: United States | F14: Customer Site Installation | G14: 45959 | H14: 45961 | I14: =H14-G14+1 -> 3 | J14: =COUNTIFS('Expense Details'!$G$2:$G$2955,$A14) -> 11 | K14: =SUMIFS('Expense Details'!$V$2:$V$2955,'Expense Details'!$G$2:$G$2955,$A14) -> 1756.43 | L14: =IFERROR(K14/I14,0) -> 585.47667 | M14: =COUNTIFS('Expense Details'!$G$2:$G$2955,$A14,'Expense Details'!$AA$2:$AA$2955,"Yes") -> 1 | N14: =SUMIFS('Expense Details'!$AF$2:$AF$2955,'Expense Details'!$G$2:$G$2955,$A14) -> 107.83 | O14: BLUEPEAK-7702 | P14: Yes | Q14: Approved
A15: TRP-2025-012 | B15: Diane Okafor | C15: Executive | D15: San Jose | E15: United States | F15: Client Meeting | G15: 45908 | H15: 45914 | I15: =H15-G15+1 -> 7 | J15: =COUNTIFS('Expense Details'!$G$2:$G$2955,$A15) -> 25 | K15: =SUMIFS('Expense Details'!$V$2:$V$2955,'Expense Details'!$G$2:$G$2955,$A15) -> 3302.63 | L15: =IFERROR(K15/I15,0) -> 471.80429 | M15: =COUNTIFS('Expense Details'!$G$2:$G$2955,$A15,'Expense Details'!$AA$2:$AA$2955,"Yes") -> 4 | N15: =SUMIFS('Expense Details'!$AF$2:$AF$2955,'Expense Details'!$G$2:$G$2955,$A15) -> 357.2 | O15: ORBITAL-8834 | P15: Yes | Q15: Pending Approval
... A141: TRP-2025-138 | B141: Hannah Weiss | C141: Field Engineering | D141: Tokyo | E141: Japan | F141: Trade Show / Conference | G141: 45897 | H141: 45901 | I141: =H141-G141+1 -> 5 | J141: =COUNTIFS('Expense Details'!$G$2:$G$2955,$A141) -> 20 | K141: =SUMIFS('Expense Details'!$V$2:$V$2955,'Expense Details'!$G$2:$G$2955,$A141) -> 4567.5639 | L141: =IFERROR(K141/I141,0) -> 913.51278 | M141: =COUNTIFS('Expense Details'!$G$2:$G$2955,$A141,'Expense Details'!$AA$2:$AA$2955,"Yes") -> 3 | N141: =SUMIFS('Expense Details'!$AF$2:$AF$2955,'Expense Details'!$G$2:$G$2955,$A141) -> 2616.725 | O141: MERIDIAN-4415 | P141: Yes | Q141: Approved
A142: TOTAL | J142: =SUM(J4:J141) -> 2954 | K142: =SUM(K4:K141) -> 476910.79 | M142: =SUM(M4:M141) -> 318 | N142: =SUM(N4:N141) -> 191871.42

Sheet Employee Summary
A1: Helios Instruments Pvt. Ltd. — Travel Spend by Employee, 2025
A3: Employee ID | B3: Employee Name | C3: Department | D3: Job Title | E3: Manager / Approver | F3: Trips Taken | G3: Expense Line Items | H3: Total Spend (USD) | I3: Airfare (USD) | J3: Lodging (USD) | K3: Meals (USD) | L3: Ground Transport (USD) | M3: Other (USD) | N3: Items Over Policy | O3: Missing Receipts | P3: Reimbursable (USD) | Q3: Avg Spend per Trip (USD) | R3: % of Company Travel Spend
A4: EMP-1712 | B4: Aisha Bello | C4: Operations | D4: Logistics Analyst | E4: Viktor Petrov | F4: 10 | G4: =COUNTIFS('Expense Details'!$B$2:$B$2955,$A4) -> 177 | H4: =SUMIFS('Expense Details'!$V$2:$V$2955,'Expense Details'!$B$2:$B$2955,$A4) -> 28793.899 | I4: =SUMIFS('Expense Details'!$V$2:$V$2955,'Expense Details'!$B$2:$B$2955,$A4,'Expense Details'!$O$2:$O$2955,"Airfare") -> 14167.041 | J4: =SUMIFS('Expense Details'!$V$2:$V$2955,'Expense Details'!$B$2:$B$2955,$A4,'Expense Details'!$O$2:$O$2955,"Hotel / Lodging") -> 6455.3002 | K4: =SUMIFS('Expense Details'!$V$2:$V$2955,'Expense Details'!$B$2:$B$2955,$A4,'Expense Details'!$O$2:$O$2955,"Meals*") -> 3451.1471 | L4: =SUMIFS('Expense Details'!$V$2:$V$2955,'Expense Details'!$B$2:$B$2955,$A4,'Expense Details'!$O$2:$O$2955,"Ground Transport*")+SUMIFS('Expense Details'!$V$2:$V$2955,'Expense Details'!$B$2:$B$2955,$A4,'Expense Details'!$O$2:$O$2955,"Car Rental") -> 2696.8145 | M4: =H4-I4-J4-K4-L4 -> 2023.5964 | N4: =COUNTIFS('Expense Details'!$B$2:$B$2955,$A4,'Expense Details'!$AA$2:$AA$2955,"Yes") -> 29 | O4: =COUNTIFS('Expense Details'!$B$2:$B$2955,$A4,'Expense Details'!$AC$2:$AC$2955,"No") -> 16 | P4: =SUMIFS('Expense Details'!$AF$2:$AF$2955,'Expense Details'!$B$2:$B$2955,$A4) -> 4785.29 | Q4: =IFERROR(H4/F4,0) -> 2879.3899 | R4: =IFERROR(H4/H$28,0) -> 0.06037586
A5: EMP-1042 | B5: Ananya Sengupta | C5: Sales | D5: Regional Sales Director | E5: Marcus Bell | F5: 2 | G5: =COUNTIFS('Expense Details'!$B$2:$B$2955,$A5) -> 52 | H5: =SUMIFS('Expense Details'!$V$2:$V$2955,'Expense Details'!$B$2:$B$2955,$A5) -> 9779.0616 | I5: =SUMIFS('Expense Details'!$V$2:$V$2955,'Expense Details'!$B$2:$B$2955,$A5,'Expense Details'!$O$2:$O$2955,"Airfare") -> 3982.7963 | J5: =SUMIFS('Expense Details'!$V$2:$V$2955,'Expense Details'!$B$2:$B$2955,$A5,'Expense Details'!$O$2:$O$2955,"Hotel / Lodging") -> 3082.6695 | K5: =SUMIFS('Expense Details'!$V$2:$V$2955,'Expense Details'!$B$2:$B$2955,$A5,'Expense Details'!$O$2:$O$2955,"Meals*") -> 1251.8188 | L5: =SUMIFS('Expense Details'!$V$2:$V$2955,'Expense Details'!$B$2:$B$2955,$A5,'Expense Details'!$O$2:$O$2955,"Ground Transport*")+SUMIFS('Expense Details'!$V$2:$V$2955,'Expense Details'!$B$2:$B$2955,$A5,'Expense Details'!$O$2:$O$2955,"Car Rental") -> 995.97575 | M5: =H5-I5-J5-K5-L5 -> 465.80135 | N5: =COUNTIFS('Expense Details'!$B$2:$B$2955,$A5,'Expense Details'!$AA$2:$AA$2955,"Yes") -> 6 | O5: =COUNTIFS('Expense Details'!$B$2:$B$2955,$A5,'Expense Details'!$AC$2:$AC$2955,"No") -> 3 | P5: =SUMIFS('Expense Details'!$AF$2:$AF$2955,'Expense Details'!$B$2:$B$2955,$A5) -> 6680.8983 | Q5: =IFERROR(H5/F5,0) -> 4889.5308 | R5: =IFERROR(H5/H$28,0) -> 0.020505012
A6: EMP-1328 | B6: Arjun Deshpande | C6: Product | D6: Product Analyst | E6: Elena Duarte | F6: 8 | G6: =COUNTIFS('Expense Details'!$B$2:$B$2955,$A6) -> 184 | H6: =SUMIFS('Expense Details'!$V$2:$V$2955,'Expense Details'!$B$2:$B$2955,$A6) -> 26987.58 | I6: =SUMIFS('Expense Details'!$V$2:$V$2955,'Expense Details'!$B$2:$B$2955,$A6,'Expense Details'!$O$2:$O$2955,"Airfare") -> 13234.589 | J6: =SUMIFS('Expense Details'!$V$2:$V$2955,'Expense Details'!$B$2:$B$2955,$A6,'Expense Details'!$O$2:$O$2955,"Hotel / Lodging") -> 6798.8229 | K6: =SUMIFS('Expense Details'!$V$2:$V$2955,'Expense Details'!$B$2:$B$2955,$A6,'Expense Details'!$O$2:$O$2955,"Meals*") -> 3773.7168 | L6: =SUMIFS('Expense Details'!$V$2:$V$2955,'Expense Details'!$B$2:$B$2955,$A6,'Expense Details'!$O$2:$O$2955,"Ground Transport*")+SUMIFS('Expense Details'!$V$2:$V$2955,'Expense Details'!$B$2:$B$2955,$A6,'Expense Details'!$O$2:$O$2955,"Car Rental") -> 2117.3822 | M6: =H6-I6-J6-K6-L6 -> 1063.0684 | N6: =COUNTIFS('Expense Details'!$B$2:$B$2955,$A6,'Expense Details'!$AA$2:$AA$2955,"Yes") -> 22 | O6: =COUNTIFS('Expense Details'!$B$2:$B$2955,$A6,'Expense Details'!$AC$2:$AC$2955,"No") -> 20 | P6: =SUMIFS('Expense Details'!$AF$2:$AF$2955,'Expense Details'!$B$2:$B$2955,$A6) -> 11749.822 | Q6: =IFERROR(H6/F6,0) -> 3373.4475 | R6: =IFERROR(H6/H$28,0) -> 0.056588318
A7: EMP-1118 | B7: Clara Jensen | C7: Sales | D7: Account Executive | E7: Ananya Sengupta | F7: 3 | G7: =COUNTIFS('Expense Details'!$B$2:$B$2955,$A7) -> 60 | H7: =SUMIFS('Expense Details'!$V$2:$V$2955,'Expense Details'!$B$2:$B$2955,$A7) -> 10124.951 | I7: =SUMIFS('Expense Details'!$V$2:$V$2955,'Expense Details'!$B$2:$B$2955,$A7,'Expense Details'!$O$2:$O$2955,"Airfare") -> 5574.2693 | J7: =SUMIFS('Expense Details'!$V$2:$V$2955,'Expense Details'!$B$2:$B$2955,$A7,'Expense Details'!$O$2:$O$2955,"Hotel / Lodging") -> 2035.477 | K7: =SUMIFS('Expense Details'!$V$2:$V$2955,'Expense Details'!$B$2:$B$2955,$A7,'Expense Details'!$O$2:$O$2955,"Meals*") -> 1195.5374 | L7: =SUMIFS('Expense Details'!$V$2:$V$2955,'Expense Details'!$B$2:$B$2955,$A7,'Expense Details'!$O$2:$O$2955,"Ground Transport*")+SUMIFS('Expense Details'!$V$2:$V$2955,'Expense Details'!$B$2:$B$2955,$A7,'Expense Details'!$O$2:$O$2955,"Car Rental") -> 856.47886 | M7: =H7-I7-J7-K7-L7 -> 463.18805 | N7: =COUNTIFS('Expense Details'!$B$2:$B$2955,$A7,'Expense Details'!$AA$2:$AA$2955,"Yes") -> 4 | O7: =COUNTIFS('Expense Details'!$B$2:$B$2955,$A7,'Expense Details'!$AC$2:$AC$2955,"No") -> 5 | P7: =SUMIFS('Expense Details'!$AF$2:$AF$2955,'Expense Details'!$B$2:$B$2955,$A7) -> 1358.0296 | Q7: =IFERROR(H7/F7,0) -> 3374.9835 | R7: =IFERROR(H7/H$28,0) -> 0.021230282
A8: EMP-1601 | B8: David Chen | C8: Finance | D8: Financial Controller | E8: Diane Okafor | F8: 8 | G8: =COUNTIFS('Expense Details'!$B$2:$B$2955,$A8) -> 158 | H8: =SUMIFS('Expense Details'!$V$2:$V$2955,'Expense Details'!$B$2:$B$2955,$A8) -> 27893.451 | I8: =SUMIFS('Expense Details'!$V$2:$V$2955,'Expense Details'!$B$2:$B$2955,$A8,'Expense Details'!$O$2:$O$2955,"Airfare") -> 13592.045 | J8: =SUMIFS('Expense Details'!$V$2:$V$2955,'Expense Details'!$B$2:$B$2955,$A8,'Expense Details'!$O$2:$O$2955,"Hotel / Lodging") -> 6582.9584 | K8: =SUMIFS('Expense Details'!$V$2:$V$2955,'Expense Details'!$B$2:$B$2955,$A8,'Expense Details'!$O$2:$O$2955,"Meals*") -> 3075.1555 | L8: =SUMIFS('Expense Details'!$V$2:$V$2955,'Expense Details'!$B$2:$B$2955,$A8,'Expense Details'!$O$2:$O$2955,"Ground Transport*")+SUMIFS('Expense Details'!$V$2:$V$2955,'Expense Details'!$B$2:$B$2955,$A8,'Expense Details'!$O$2:$O$2955,"Car Rental") -> 1387.1194 | M8: =H8-I8-J8-K8-L8 -> 3256.1732 | N8: =COUNTIFS('Expense Details'!$B$2:$B$2955,$A8,'Expense Details'!$AA$2:$AA$2955,"Yes") -> 20 | O8: =COUNTIFS('Expense Details'!$B$2:$B$2955,$A8,'Expense Details'!$AC$2:$AC$2955,"No") -> 18 | P8: =SUMIFS('Expense Details'!$AF$2:$AF$2955,'Expense Details'!$B$2:$B$2955,$A8) -> 13608.104 | Q8: =IFERROR(H8/F8,0) -> 3486.6814 | R8: =IFERROR(H8/H$28,0) -> 0.058487775
A9: EMP-1701 | B9: Diane Okafor | C9: Executive | D9: Chief Operating Officer | E9: Board | F9: 3 | G9: =COUNTIFS('Expense Details'!$B$2:$B$2955,$A9) -> 49 | H9: =SUMIFS('Expense Details'!$V$2:$V$2955,'Expense Details'!$B$2:$B$2955,$A9) -> 7241.4838 | I9: =SUMIFS('Expense Details'!$V$2:$V$2955,'Expense Details'!$B$2:$B$2955,$A9,'Expense Details'!$O$2:$O$2955,"Airfare") -> 3388.3818 | J9: =SUMIFS('Expense Details'!$V$2:$V$2955,'Expense Details'!$B$2:$B$2955,$A9,'Expense Details'!$O$2:$O$2955,"Hotel / Lodging") -> 2044.1078 | K9: =SUMIFS('Expense Details'!$V$2:$V$2955,'Expense Details'!$B$2:$B$2955,$A9,'Expense Details'!$O$2:$O$2955,"Meals*") -> 1140.0866 | L9: =SUMIFS('Expense Details'!$V$2:$V$2955,'Expense Details'!$B$2:$B$2955,$A9,'Expense Details'!$O$2:$O$2955,"Ground Transport*")+SUMIFS('Expense Details'!$V$2:$V$2955,'Expense Details'!$B$2:$B$2955,$A9,'Expense Details'!$O$2:$O$2955,"Car Rental") -> 300.0728 | M9: =H9-I9-J9-K9-L9 -> 368.8349 | N9: =COUNTIFS('Expense Details'!$B$2:$B$2955,$A9,'Expense Details'!$AA$2:$AA$2955,"Yes") -> 5 | O9: =COUNTIFS('Expense Details'!$B$2:$B$2955,$A9,'Expense Details'!$AC$2:$AC$2955,"No") -> 3 | P9: =SUMIFS('Expense Details'!$AF$2:$AF$2955,'Expense Details'!$B$2:$B$2955,$A9) -> 2717.2594 | Q9: =IFERROR(H9/F9,0) -> 2413.8279 | R9: =IFERROR(H9/H$28,0) -> 0.015184148
A10: EMP-1125 | B10: Diego Ramirez | C10: Sales | D10: Account Executive | E10: Marcus Bell | F10: 2 | G10: =COUNTIFS('Expense Details'!$B$2:$B$2955,$A10) -> 27 | H10: =SUMIFS('Expense Details'!$V$2:$V$2955,'Expense Details'!$B$2:$B$2955,$A10) -> 3379.1106 | I10: =SUMIFS('Expense Details'!$V$2:$V$2955,'Expense Details'!$B$2:$B$2955,$A10,'Expense Details'!$O$2:$O$2955,"Airfare") -> 1848.2821 | J10: =SUMIFS('Expense Details'!$V$2:$V$2955,'Expense Details'!$B$2:$B$2955,$A10,'Expense Details'!$O$2:$O$2955,"Hotel / Lodging") -> 579.04661 | K10: =SUMIFS('Expense Details'!$V$2:$V$2955,'Expense Details'!$B$2:$B$2955,$A10,'Expense Details'!$O$2:$O$2955,"Meals*") -> 613.2382 | L10: =SUMIFS('Expense Details'!$V$2:$V$2955,'Expense Details'!$B$2:$B$2955,$A10,'Expense Details'!$O$2:$O$2955,"Ground Transport*")+SUMIFS('Expense Details'!$V$2:$V$2955,'Expense Details'!$B$2:$B$2955,$A10,'Expense Details'!$O$2:$O$2955,"Car Rental") -> 195.52465 | M10: =H10-I10-J10-K10-L10 -> 143.01896 | N10: =COUNTIFS('Expense Details'!$B$2:$B$2955,$A10,'Expense Details'!$AA$2:$AA$2955,"Yes") -> 3 | O10: =COUNTIFS('Expense Details'!$B$2:$B$2955,$A10,'Expense Details'!$AC$2:$AC$2955,"No") -> 2 | P10: =SUMIFS('Expense Details'!$AF$2:$AF$2955,'Expense Details'!$B$2:$B$2955,$A10) -> 1466.8698 | Q10: =IFERROR(H10/F10,0) -> 1689.5553 | R10: =IFERROR(H10/H$28,0) -> 0.0070854143
A11: EMP-1315 | B11: Elena Duarte | C11: Product | D11: Director of Product | E11: Diane Okafor | F11: 7 | G11: =COUNTIFS('Expense Details'!$B$2:$B$2955,$A11) -> 165 | H11: =SUMIFS('Expense Details'!$V$2:$V$2955,'Expense Details'!$B$2:$B$2955,$A11) -> 20673.856 | I11: =SUMIFS('Expense Details'!$V$2:$V$2955,'Expense Details'!$B$2:$B$2955,$A11,'Expense Details'!$O$2:$O$2955,"Airfare") -> 6876.663 | J11: =SUMIFS('Expense Details'!$V$2:$V$2955,'Expense Details'!$B$2:$B$2955,$A11,'Expense Details'!$O$2:$O$2955,"Hotel / Lodging") -> 5333.8525 | K11: =SUMIFS('Expense Details'!$V$2:$V$2955,'Expense Details'!$B$2:$B$2955,$A11,'Expense Details'!$O$2:$O$2955,"Meals*") -> 3288.6768 | L11: =SUMIFS('Expense Details'!$V$2:$V$2955,'Expense Details'!$B$2:$B$2955,$A11,'Expense Details'!$O$2:$O$2955,"Ground Transport*")+SUMIFS('Expense Details'!$V$2:$V$2955,'Expense Details'!$B$2:$B$2955,$A11,'Expense Details'!$O$2:$O$2955,"Car Rental") -> 3364.0694 | M11: =H11-I11-J11-K11-L11 -> 1810.5942 | N11: =COUNTIFS('Expense Details'!$B$2:$B$2955,$A11,'Expense Details'!$AA$2:$AA$2955,"Yes") -> 14 | O11: =COUNTIFS('Expense Details'!$B$2:$B$2955,$A11,'Expense Details'!$AC$2:$AC$2955,"No") -> 13 | P11: =SUMIFS('Expense Details'!$AF$2:$AF$2955,'Expense Details'!$B$2:$B$2955,$A11) -> 5258.2279 | Q11: =IFERROR(H11/F11,0) -> 2953.408 | R11: =IFERROR(H11/H$28,0) -> 0.043349525
A12: EMP-1401 | B12: Fatima Al-Rashid | C12: Marketing | D12: Marketing Manager | E12: Grace Lin | F12: 3 | G12: =COUNTIFS('Expense Details'!$B$2:$B$2955,$A12) -> 52 | H12: =SUMIFS('Expense Details'!$V$2:$V$2955,'Expense Details'!$B$2:$B$2955,$A12) -> 8421.8617 | I12: =SUMIFS('Expense Details'!$V$2:$V$2955,'Expense Details'!$B$2:$B$2955,$A12,'Expense Details'!$O$2:$O$2955,"Airfare") -> 3929.0908 | J12: =SUMIFS('Expense Details'!$V$2:$V$2955,'Expense Details'!$B$2:$B$2955,$A12,'Expense Details'!$O$2:$O$2955,"Hotel / Lodging") -> 1928.3655 | K12: =SUMIFS('Expense Details'!$V$2:$V$2955,'Expense Details'!$B$2:$B$2955,$A12,'Expense Details'!$O$2:$O$2955,"Meals*") -> 1004.3143 | L12: =SUMIFS('Expense Details'!$V$2:$V$2955,'Expense Details'!$B$2:$B$2955,$A12,'Expense Details'!$O$2:$O$2955,"Ground Transport*")+SUMIFS('Expense Details'!$V$2:$V$2955,'Expense Details'!$B$2:$B$2955,$A12,'Expense Details'!$O$2:$O$2955,"Car Rental") -> 613.02197 | M12: =H12-I12-J12-K12-L12 -> 947.06921 | N12: =COUNTIFS('Expense Details'!$B$2:$B$2955,$A12,'Expense Details'!$AA$2:$AA$2955,"Yes") -> 6 | O12: =COUNTIFS('Expense Details'!$B$2:$B$2955,$A12,'Expense Details'!$AC$2:$AC$2955,"No") -> 6 | P12: =SUMIFS('Expense Details'!$AF$2:$AF$2955,'Expense Details'!$B$2:$B$2955,$A12) -> 4661.6606 | Q12: =IFERROR(H12/F12,0) -> 2807.2872 | R12: =IFERROR(H12/H$28,0) -> 0.017659197
A13: EMP-1409 | B13: Grace Lin | C13: Marketing | D13: Head of Marketing | E13: Diane Okafor | F13: 5 | G13: =COUNTIFS('Expense Details'!$B$2:$B$2955,$A13) -> 92 | H13: =SUMIFS('Expense Details'!$V$2:$V$2955,'Expense Details'!$B$2:$B$2955,$A13) -> 16402.288 | I13: =SUMIFS('Expense Details'!$V$2:$V$2955,'Expense Details'!$B$2:$B$2955,$A13,'Expense Details'!$O$2:$O$2955,"Airfare") -> 9156.1619 | J13: =SUMIFS('Expense Details'!$V$2:$V$2955,'Expense Details'!$B$2:$B$2955,$A13,'Expense Details'!$O$2:$O$2955,"Hotel / Lodging") -> 3058.0002 | K13: =SUMIFS('Expense Details'!$V$2:$V$2955,'Expense Details'!$B$2:$B$2955,$A13,'Expense Details'!$O$2:$O$2955,"Meals*") -> 1734.3755 | L13: =SUMIFS('Expense Details'!$V$2:$V$2955,'Expense Details'!$B$2:$B$2955,$A13,'Expense Details'!$O$2:$O$2955,"Ground Transport*")+SUMIFS('Expense Details'!$V$2:$V$2955,'Expense Details'!$B$2:$B$2955,$A13,'Expense Details'!$O$2:$O$2955,"Car Rental") -> 938.56961 | M13: =H13-I13-J13-K13-L13 -> 1515.1806 | N13: =COUNTIFS('Expense Details'!$B$2:$B$2955,$A13,'Expense Details'!$AA$2:$AA$2955,"Yes") -> 14 | O13: =COUNTIFS('Expense Details'!$B$2:$B$2955,$A13,'Expense Details'!$AC$2:$AC$2955,"No") -> 10 | P13: =SUMIFS('Expense Details'!$AF$2:$AF$2955,'Expense Details'!$B$2:$B$2955,$A13) -> 5189.985 | Q13: =IFERROR(H13/F13,0) -> 3280.4576 | R13: =IFERROR(H13/H$28,0) -> 0.03439278
A14: EMP-1236 | B14: Hannah Weiss | C14: Field Engineering | D14: Field Engineer | E14: Tomas Kovac | F14: 8 | G14: =COUNTIFS('Expense Details'!$B$2:$B$2955,$A14) -> 163 | H14: =SUMIFS('Expense Details'!$V$2:$V$2955,'Expense Details'!$B$2:$B$2955,$A14) -> 31010.728 | I14: =SUMIFS('Expense Details'!$V$2:$V$2955,'Expense Details'!$B$2:$B$2955,$A14,'Expense Details'!$O$2:$O$2955,"Airfare") -> 14829.36 | J14: =SUMIFS('Expense Details'!$V$2:$V$2955,'Expense Details'!$B$2:$B$2955,$A14,'Expense Details'!$O$2:$O$2955,"Hotel / Lodging") -> 6106.7777 | K14: =SUMIFS('Expense Details'!$V$2:$V$2955,'Expense Details'!$B$2:$B$2955,$A14,'Expense Details'!$O$2:$O$2955,"Meals*") -> 3619.6348 | L14: =SUMIFS('Expense Details'!$V$2:$V$2955,'Expense Details'!$B$2:$B$2955,$A14,'Expense Details'!$O$2:$O$2955,"Ground Transport*")+SUMIFS('Expense Details'!$V$2:$V$2955,'Expense Details'!$B$2:$B$2955,$A14,'Expense Details'!$O$2:$O$2955,"Car Rental") -> 1875.2455 | M14: =H14-I14-J14-K14-L14 -> 4579.7098 | N14: =COUNTIFS('Expense Details'!$B$2:$B$2955,$A14,'Expense Details'!$AA$2:$AA$2955,"Yes") -> 24 | O14: =COUNTIFS('Expense Details'!$B$2:$B$2955,$A14,'Expense Details'!$AC$2:$AC$2955,"No") -> 11 | P14: =SUMIFS('Expense Details'!$AF$2:$AF$2955,'Expense Details'!$B$2:$B$2955,$A14) -> 18000.695 | Q14: =IFERROR(H14/F14,0) -> 3876.341 | R14: =IFERROR(H14/H$28,0) -> 0.06502417
A15: EMP-1302 | B15: Kenji Watanabe | C15: Product | D15: Product Manager | E15: Elena Duarte | F15: 5 | G15: =COUNTIFS('Expense Details'!$B$2:$B$2955,$A15) -> 111 | H15: =SUMIFS('Expense Details'!$V$2:$V$2955,'Expense Details'!$B$2:$B$2955,$A15) -> 18037.077 | I15: =SUMIFS('Expense Details'!$V$2:$V$2955,'Expense Details'!$B$2:$B$2955,$A15,'Expense Details'!$O$2:$O$2955,"Airfare") -> 6454.8436 | J15: =SUMIFS('Expense Details'!$V$2:$V$2955,'Expense Details'!$B$2:$B$2955,$A15,'Expense Details'!$O$2:$O$2955,"Hotel / Lodging") -> 6604.9785 | K15: =SUMIFS('Expense Details'!$V$2:$V$2955,'Expense Details'!$B$2:$B$2955,$A15,'Expense Details'!$O$2:$O$2955,"Meals*") -> 2389.5842 | L15: =SUMIFS('Expense Details'!$V$2:$V$2955,'Expense Details'!$B$2:$B$2955,$A15,'Expense Details'!$O$2:$O$2955,"Ground Transport*")+SUMIFS('Expense Details'!$V$2:$V$2955,'Expense Details'!$B$2:$B$2955,$A15,'Expense Details'!$O$2:$O$2955,"Car Rental") -> 2367.2176 | M15: =H15-I15-J15-K15-L15 -> 220.45271 | N15: =COUNTIFS('Expense Details'!$B$2:$B$2955,$A15,'Expense Details'!$AA$2:$AA$2955,"Yes") -> 14 | O15: =COUNTIFS('Expense Details'!$B$2:$B$2955,$A15,'Expense Details'!$AC$2:$AC$2955,"No") -> 14 | P15: =SUMIFS('Expense Details'!$AF$2:$AF$2955,'Expense Details'!$B$2:$B$2955,$A15) -> 10842.149 | Q15: =IFERROR(H15/F15,0) -> 3607.4153 | R15: =IFERROR(H15/H$28,0) -> 0.037820651
... A27: EMP-1705 | B27: Viktor Petrov | C27: Operations | D27: Supply Chain Manager | E27: Diane Okafor | F27: 7 | G27: =COUNTIFS('Expense Details'!$B$2:$B$2955,$A27) -> 123 | H27: =SUMIFS('Expense Details'!$V$2:$V$2955,'Expense Details'!$B$2:$B$2955,$A27) -> 19907.486 | I27: =SUMIFS('Expense Details'!$V$2:$V$2955,'Expense Details'!$B$2:$B$2955,$A27,'Expense Details'!$O$2:$O$2955,"Airfare") -> 9130.0028 | J27: =SUMIFS('Expense Details'!$V$2:$V$2955,'Expense Details'!$B$2:$B$2955,$A27,'Expense Details'!$O$2:$O$2955,"Hotel / Lodging") -> 5215.6216 | K27: =SUMIFS('Expense Details'!$V$2:$V$2955,'Expense Details'!$B$2:$B$2955,$A27,'Expense Details'!$O$2:$O$2955,"Meals*") -> 2269.4788 | L27: =SUMIFS('Expense Details'!$V$2:$V$2955,'Expense Details'!$B$2:$B$2955,$A27,'Expense Details'!$O$2:$O$2955,"Ground Transport*")+SUMIFS('Expense Details'!$V$2:$V$2955,'Expense Details'!$B$2:$B$2955,$A27,'Expense Details'!$O$2:$O$2955,"Car Rental") -> 1349.1787 | M27: =H27-I27-J27-K27-L27 -> 1943.2041 | N27: =COUNTIFS('Expense Details'!$B$2:$B$2955,$A27,'Expense Details'!$AA$2:$AA$2955,"Yes") -> 13 | O27: =COUNTIFS('Expense Details'!$B$2:$B$2955,$A27,'Expense Details'!$AC$2:$AC$2955,"No") -> 10 | P27: =SUMIFS('Expense Details'!$AF$2:$AF$2955,'Expense Details'!$B$2:$B$2955,$A27) -> 6176.3175 | Q27: =IFERROR(H27/F27,0) -> 2843.9266 | R27: =IFERROR(H27/H$28,0) -> 0.041742578
A28: TOTAL | F28: =SUM(F4:F27) -> 138 | G28: =SUM(G4:G27) -> 2954 | H28: =SUM(H4:H27) -> 476910.79 | I28: =SUM(I4:I27) -> 214763.68 | J28: =SUM(J4:J27) -> 118139.44 | K28: =SUM(K4:K27) -> 60058.949 | L28: =SUM(L4:L27) -> 38733.811 | M28: =SUM(M4:M27) -> 45214.92 | ... P28: =SUM(P4:P27) -> 191871.42 | Q28: =IFERROR(H28/F28,0) -> 3455.8753 | R28: 1

Sheet Category by Month
A1: Helios Instruments Pvt. Ltd. — Travel Spend by Category and Month, 2025
